# ES6 Promises

Hey there! So, I've been diving into ES6 Promises lately, and let me tell you, it's been quite the journey! As a software engineering student, I'm always eager to learn new concepts, and Promises have definitely caught my attention.

## Getting Started with Promises

At first, I was intrigued by the concept of Promises. They seemed like a cleaner way to handle asynchronous operations compared to traditional callbacks. I mean, who wants to deal with callback hell, right? With Promises, I could finally write asynchronous code in a more organized and readable manner.

```javascript
const myPromise = new Promise((resolve, reject) => {
  setTimeout(() => {
    resolve('Data fetched successfully');
  }, 2000);
});

myPromise
  .then((data) => {
    console.log(data);
  })
  .catch((error) => {
    console.error(error);
  });
```

## Exploring Promise Methods

As I delved deeper into Promises, I discovered some interesting methods that made my life a lot easier. The `then` method, for example, allowed me to handle the successful fulfillment of a Promise, while the `catch` method caught any errors that occurred during the operation.

```javascript
myPromise
  .then((data) => {
    console.log(data); // Output: Data fetched successfully
  })
  .catch((error) => {
    console.error(error);
  });
```

But wait, there's more! I also learned about the `every` method of the Promise object. This nifty little method allowed me to wait for all promises in an iterable to be fulfilled or for any to be rejected. It was like having superpowers to control the flow of asynchronous operations!

```javascript
const promise1 = Promise.resolve(3);
const promise2 = 42;
const promise3 = new Promise((resolve, reject) => {
  setTimeout(resolve, 100, 'foo');
});

Promise.every([promise1, promise2, promise3]).then((values) => {
  console.log(values); // Output: [3, 42, "foo"]
});
```

## Throw / Try

When it comes to handling errors in Promises, the `throw` statement combined with `try` and `catch` blocks can be incredibly useful. It allows you to throw an exception inside a Promise and catch it using a `catch` block.

```javascript
const myPromise = new Promise((resolve, reject) => {
  setTimeout(() => {
    try {
      throw new Error('Something went wrong');
    } catch (error) {
      reject(error);
    }
  }, 2000);
});

myPromise.catch((error) => {
  console.error(error); // Output: Error: Something went wrong
});
```

## The `await` Operator

Ah, the `await` operator! This little gem is used to wait for a Promise to settle and obtain its result. It can only be used inside an `async` function, which allows you to write asynchronous code in a more synchronous style.

```javascript
async function fetchData() {
  try {
    const data = await myPromise;
    console.log(data); // Output: Data fetched successfully
  } catch (error) {
    console.error(error);
  }
}

fetchData();
```

## How to Use an Async Function

Lastly, async functions provide a cleaner and more readable way to work with asynchronous code. They automatically return a Promise and allow you to use the `await` keyword to wait for other asynchronous operations to complete.

```javascript
async function getData() {
  try {
    const data = await fetchData();
    console.log(data); // Output: Data fetched successfully
  } catch (error) {
    console.error(error);
  }
}

getData();
```

Overall, my journey with ES6 Promises has been both challenging and rewarding. I've learned how to handle asynchronous operations more effectively, thanks to the power of Promises and their methods. And I can't wait to continue exploring and applying these concepts in my future projects. Cheers to the wonderful world of asynchronous JavaScript programming! ðŸŽ‰
